Workbook

Sheet Ringkasan
A1: Metrik | B1: Nilai
A2: Jumlah artikel | B2: =COUNTA(Artikel!A2:A2182) -> 2181
A3: Artikel dengan ≥1 tempat | B3: =COUNTIF(Artikel!C2:C2182,">0") -> 1049
A4: Jumlah baris tempat | B4: =COUNTA(Tempat!A2:A1789) -> 1788
A5: Tempat viral eksplisit | B5: =COUNTIF(Tempat!Q2:Q1789,"Ya") -> 492
A6: Kategori: Kafe | B6: =COUNTIF(Tempat!D2:D1789,"Kafe") -> 216
A7: Kategori: Restoran | B7: =COUNTIF(Tempat!D2:D1789,"Restoran") -> 583
A8: Kategori: Wisata Alam | B8: =COUNTIF(Tempat!D2:D1789,"Wisata Alam") -> 380
A9: Kategori: Museum | B9: =COUNTIF(Tempat!D2:D1789,"Museum") -> 110
A10: Kategori: Wahana | B10: =COUNTIF(Tempat!D2:D1789,"Wahana") -> 53
A11: Kategori: Pameran | B11: =COUNTIF(Tempat!D2:D1789,"Pameran") -> 204
A12: Kategori: lainnya | B12: =COUNTIF(Tempat!D2:D1789,"lainnya") -> 242
A13: Artikel judul Sesuai | B13: =COUNTIF(Artikel!K2:K2182,"Sesuai") -> 282
A14: Artikel judul Ragu | B14: =COUNTIF(Artikel!K2:K2182,"Ragu") -> 58
A15: Artikel judul Tidak sesuai (isi = judul artikel N-1) | B15: =COUNTIF(Artikel!K2:K2182,"Tidak sesuai (isi = judul artikel N-1)") -> 426
A16: Artikel judul Tidak sesuai | B16: =COUNTIF(Artikel!K2:K2182,"Tidak sesuai") -> 1415
A18: Catatan pergeseran data:
A19: • Isi artikel konsisten cocok dengan final_url (lihat "skor URL vs isi" di sheet Artikel) — jadi final_url adalah sumber yang benar untuk setiap tempat.
A20: • Yang bergeser adalah judul/source/published di id_map: sering bukan milik isi tersebut.
A21: • id ~242–800: isi umumnya milik judul artikel N-1 (bergeser 1). Setelah ~800: judul dan isi teracak (isi cocok dengan judul yang jaraknya jauh, sering ±640–650 id).
A22: • Ekstraksi tempat selalu berdasarkan ISI. Bila "judul sesuai isi?" = Tidak sesuai, abaikan judul/source/published dan rujuk final_url.
A24: Catatan kolom lokasi:
A25: • Kelurahan/kecamatan/kota/provinsi diambil dari lokasi_text; tingkat yang tidak disebut dilengkapi dari pengetahuan geografis hanya bila yakin (lihat kolom "sumber wilayah": teks / teks+inferensi / inferensi). Kosong = tidak disebut & tidak yakin.
A26: • Koordinat TIDAK berasal dari layanan geocoding (akses internet diblokir di lingkungan kerja), melainkan perkiraan. Kolom "presisi koordinat" menjelaskan titik apa yang diwakili: titik tempat (landmark terkenal) atau pusat kelurahan/kecamatan/kota/provinsi.
A27: • Sudah divalidasi otomatis: nama provinsi (38 resmi, termasuk pemekaran Papua), konsistensi kota/kabupaten→provinsi, dan koordinat berada dalam batas provinsinya. Untuk analisis tingkat titik, sebaiknya verifikasi ulang dengan Google Maps/geocoder.
A28: • Nama kota yang ambigu (mis. "Bogor", "Malang", "Bekasi" tanpa keterangan Kota/Kabupaten) dibiarkan kosong di kolom kota/kabupaten; koordinat memakai pusat provinsi.

Sheet Tempat
A1: article_id | B1: batch | C1: nama_tempat | D1: kategori | E1: lokasi_text | F1: kelurahan/desa | G1: kecamatan | H1: kota/kabupaten | I1: provinsi | J1: latitude | K1: longitude | L1: presisi koordinat | M1: sumber wilayah | N1: catatan lokasi | O1: alasan_viral | P1: indikasi_waktu | Q1: is_explicitly_viral | R1: confidence | S1: final_url (sumber isi) | T1: domain URL | U1: judul (id_map) | V1: source (id_map) | W1: published (id_map) | X1: judul sesuai isi?
A2: 1 | B2: 001 | C2: Soto Mie Agih | D2: Restoran | E2: Jalan Suryakencana No.313, Babakan Pasar, Bogor Tengah, Bogor | F2: Babakan Pasar | G2: Bogor Tengah | H2: Kota Bogor | I2: Jawa Barat | J2: -6.605 | K2: 106.8 | L2: Pusat kelurahan/desa | M2: teks+inferensi | O2: Soto mie legendaris Bogor sejak 1965-an, menu babat hingga jumbo | Q2: Tidak | R2: 0.9 | S2: https://food.detik.com/rumah-makan/d-8679688/awas-kalap-ini-7-tempat-makan-soto-mie-legendaris-di-jakarta-dan-bogor | T2: food.detik.com | U2: Awas Kalap! Ini 7 Tempat Makan Soto Mie Legendaris di Jakarta dan Bogor - detikFood | V2: detikFood | W2: 2026-09-26 | X2: Sesuai
A3: 1 | B3: 001 | C3: Soto Mie Sarodja | D3: Restoran | E3: Jalan Danau Tondano No.27, Pejompongan, Jakarta Pusat | F3: Bendungan Hilir | G3: Tanah Abang | H3: Kota Jakarta Pusat | I3: DKI Jakarta | J3: -6.209 | K3: 106.81 | L3: Pusat kelurahan/desa | M3: teks+inferensi | N3: Pejompongan adalah kawasan di Kel. Bendungan Hilir | O3: Soto mie sejak 1970, diteruskan generasi kedua | Q3: Tidak | R3: 0.9 | S3: https://food.detik.com/rumah-makan/d-8679688/awas-kalap-ini-7-tempat-makan-soto-mie-legendaris-di-jakarta-dan-bogor | T3: food.detik.com | U3: Awas Kalap! Ini 7 Tempat Makan Soto Mie Legendaris di Jakarta dan Bogor - detikFood | V3: detikFood | W3: 2026-09-26 | X3: Sesuai
A4: 1 | B4: 001 | C4: Soto Mie Theresia | D4: Restoran | E4: Jalan Gereja Theresia No.43, Menteng, Jakarta Pusat | F4: Gondangdia | G4: Menteng | H4: Kota Jakarta Pusat | I4: DKI Jakarta | J4: -6.188 | K4: 106.827 | L4: Pusat kelurahan/desa | M4: teks+inferensi | O4: Soto mie legendaris sejak 1972 di kawasan Kuliner Theresia | Q4: Tidak | R4: 0.9 | S4: https://food.detik.com/rumah-makan/d-8679688/awas-kalap-ini-7-tempat-makan-soto-mie-legendaris-di-jakarta-dan-bogor | T4: food.detik.com | U4: Awas Kalap! Ini 7 Tempat Makan Soto Mie Legendaris di Jakarta dan Bogor - detikFood | V4: detikFood | W4: 2026-09-26 | X4: Sesuai
A5: 1 | B5: 001 | C5: Soto Mie Pak Fauzy | D5: Restoran | E5: Kawasan Suryakencana, Bogor | G5: Bogor Tengah | H5: Kota Bogor | I5: Jawa Barat | J5: -6.598 | K5: 106.797 | L5: Pusat kecamatan | M5: teks+inferensi | N5: Kawasan Jalan Suryakencana | O5: Soto mie legendaris sejak 1974 | Q5: Tidak | R5: 0.85 | S5: https://food.detik.com/rumah-makan/d-8679688/awas-kalap-ini-7-tempat-makan-soto-mie-legendaris-di-jakarta-dan-bogor | T5: food.detik.com | U5: Awas Kalap! Ini 7 Tempat Makan Soto Mie Legendaris di Jakarta dan Bogor - detikFood | V5: detikFood | W5: 2026-09-26 | X5: Sesuai
A6: 2 | B6: 001 | C6: Gudeg Yu Djum | D6: Restoran | E6: Jl. Wijilan No. 167, Panembahan, Kraton, Yogyakarta | F6: Panembahan | G6: Kraton | H6: Kota Yogyakarta | I6: DI Yogyakarta | J6: -7.806 | K6: 110.367 | L6: Pusat kelurahan/desa | M6: teks+inferensi | O6: Ikon gudeg Jogja sejak 1950-an, harga ekonomis | Q6: Tidak | R6: 0.9 | S6: https://rri.co.id/yogyakarta/kuliner/2752639/rekomendasi-7-tempat-makan-ramah-kantong-di-jogja-dan-tips-menggunakan-grabfood | T6: rri.co.id | U6: Rekomendasi 7 Tempat Makan Ramah Kantong di Jogja dan Tips Menggunakan GrabFood - RRI.co.id | V6: RRI.co.id | W6: 2026-09-23 | X6: Sesuai
A7: 2 | B7: 001 | C7: Gudeg Pawon | D7: Restoran | E7: Yogyakarta | H7: Kota Yogyakarta | I7: DI Yogyakarta | J7: -7.797 | K7: 110.37 | L7: Pusat kota/kabupaten | M7: teks+inferensi | O7: Gudeg dimasak langsung di dapur tradisional, pengalaman unik | Q7: Tidak | R7: 0.8 | S7: https://rri.co.id/yogyakarta/kuliner/2752639/rekomendasi-7-tempat-makan-ramah-kantong-di-jogja-dan-tips-menggunakan-grabfood | T7: rri.co.id | U7: Rekomendasi 7 Tempat Makan Ramah Kantong di Jogja dan Tips Menggunakan GrabFood - RRI.co.id | V7: RRI.co.id | W7: 2026-09-23 | X7: Sesuai
A8: 3 | B8: 001 | C8: RM Abah Harja | D8: Restoran | E8: Jl. Halimun No.8, Malabar, Kec. Lengkong, Kota Bandung | F8: Malabar | G8: Lengkong | H8: Kota Bandung | I8: Jawa Barat | J8: -6.928 | K8: 107.62 | L8: Pusat kelurahan/desa | M8: teks+inferensi | O8: Restoran Sunda baru, punya sawah dan peternakan sendiri, ayam bekakak; masuk daftar tempat makan viral Bandung 2026 | P8: 2026 | Q8: Ya | R8: 0.9 | S8: https://www.nibble.id/tempat-makan-viral-di-bandung-2026/ | T8: www.nibble.id | U8: 10 Tempat Makan Viral di Bandung 2026 - nibble.id | V8: nibble.id | W8: 2026-06-09 | X8: Sesuai
A9: 3 | B9: 001 | C9: RM Wangi Seruni | D9: Restoran | E9: Bandung | H9: Kota Bandung | I9: Jawa Barat | J9: -6.917 | K9: 107.619 | L9: Pusat kota/kabupaten | M9: teks+inferensi | N9: Bandung diasumsikan Kota Bandung | O9: Ayam goreng seruni, konsep makanan rumahan; disebut tempat makan viral Bandung 2026 | P9: 2026 | Q9: Ya | R9: 0.85 | S9: https://www.nibble.id/tempat-makan-viral-di-bandung-2026/ | T9: www.nibble.id | U9: 10 Tempat Makan Viral di Bandung 2026 - nibble.id | V9: nibble.id | W9: 2026-06-09 | X9: Sesuai
A10: 4 | B10: 001 | C10: TikTok Food Fest 2026 | D10: Pameran | E10: Hutan Kota Gelora Bung Karno (GBK), Jakarta | F10: Gelora | G10: Tanah Abang | H10: Kota Jakarta Pusat | I10: DKI Jakarta | J10: -6.2186 | K10: 106.8019 | L10: Titik tempat | M10: teks+inferensi | N10: Kawasan GBK Senayan | O10: Festival kuliner gratis dengan 40+ tenant kuliner viral TikTok | P10: 26–27 September 2026 | Q10: Ya | R10: 0.9 | S10: https://aktualita.co/ragam/tiktok-food-fest-2026-hari-terakhir-gbk | T10: aktualita.co | U10: TikTok Food Fest 2026 Hari Terakhir di GBK, Ada 40 Lebih Tenant hingga Kuliner Viral - Aktualita.co | V10: Aktualita.co | W10: 2026-09-27 | X10: Sesuai
A11: 4 | B11: 001 | C11: Mad Bagel | D11: Kafe | E11: Tenant TikTok Food Fest, GBK, Jakarta | F11: Gelora | G11: Tanah Abang | H11: Kota Jakarta Pusat | I11: DKI Jakarta | J11: -6.2186 | K11: 106.8019 | L11: Titik tempat | M11: teks+inferensi | N11: Kawasan GBK Senayan | O11: Bagel manis dan gurih, kuliner populer di media sosial | Q11: Ya | R11: 0.75 | S11: https://aktualita.co/ragam/tiktok-food-fest-2026-hari-terakhir-gbk | T11: aktualita.co | U11: TikTok Food Fest 2026 Hari Terakhir di GBK, Ada 40 Lebih Tenant hingga Kuliner Viral - Aktualita.co | V11: Aktualita.co | W11: 2026-09-27 | X11: Sesuai
A12: 4 | B12: 001 | C12: RM Lokiin | D12: Restoran | E12: Tenant TikTok Food Fest, GBK, Jakarta | F12: Gelora | G12: Tanah Abang | H12: Kota Jakarta Pusat | I12: DKI Jakarta | J12: -6.2186 | K12: 106.8019 | L12: Titik tempat | M12: teks+inferensi | N12: Kawasan GBK Senayan | O12: Nasi dengan beragam lauk termasuk nasi lidah, populer di medsos | Q12: Ya | R12: 0.75 | S12: https://aktualita.co/ragam/tiktok-food-fest-2026-hari-terakhir-gbk | T12: aktualita.co | U12: TikTok Food Fest 2026 Hari Terakhir di GBK, Ada 40 Lebih Tenant hingga Kuliner Viral - Aktualita.co | V12: Aktualita.co | W12: 2026-09-27 | X12: Sesuai
A13: 4 | B13: 001 | C13: Chuchat | D13: Kafe | E13: Tenant TikTok Food Fest, GBK, Jakarta | F13: Gelora | G13: Tanah Abang | H13: Kota Jakarta Pusat | I13: DKI Jakarta | J13: -6.2186 | K13: 106.8019 | L13: Titik tempat | M13: teks+inferensi | N13: Kawasan GBK Senayan | O13: Tenant minuman populer di media sosial | Q13: Ya | R13: 0.7 | S13: https://aktualita.co/ragam/tiktok-food-fest-2026-hari-terakhir-gbk | T13: aktualita.co | U13: TikTok Food Fest 2026 Hari Terakhir di GBK, Ada 40 Lebih Tenant hingga Kuliner Viral - Aktualita.co | V13: Aktualita.co | W13: 2026-09-27 | X13: Sesuai
A14: 4 | B14: 001 | C14: Fuku | D14: Kafe | E14: Tenant TikTok Food Fest, GBK, Jakarta | F14: Gelora | G14: Tanah Abang | H14: Kota Jakarta Pusat | I14: DKI Jakarta | J14: -6.2186 | K14: 106.8019 | L14: Titik tempat | M14: teks+inferensi | N14: Kawasan GBK Senayan | O14: Gelato mochi, populer di media sosial | Q14: Ya | R14: 0.7 | S14: https://aktualita.co/ragam/tiktok-food-fest-2026-hari-terakhir-gbk | T14: aktualita.co | U14: TikTok Food Fest 2026 Hari Terakhir di GBK, Ada 40 Lebih Tenant hingga Kuliner Viral - Aktualita.co | V14: Aktualita.co | W14: 2026-09-27 | X14: Sesuai
A15: 4 | B15: 001 | C15: Eight Tarts | D15: Kafe | E15: Tenant TikTok Food Fest, GBK, Jakarta | F15: Gelora | G15: Tanah Abang | H15: Kota Jakarta Pusat | I15: DKI Jakarta | J15: -6.2186 | K15: 106.8019 | L15: Titik tempat | M15: teks+inferensi | N15: Kawasan GBK Senayan | O15: Berbagai varian egg tart | Q15: Ya | R15: 0.7 | S15: https://aktualita.co/ragam/tiktok-food-fest-2026-hari-terakhir-gbk | T15: aktualita.co | U15: TikTok Food Fest 2026 Hari Terakhir di GBK, Ada 40 Lebih Tenant hingga Kuliner Viral - Aktualita.co | V15: Aktualita.co | W15: 2026-09-27 | X15: Sesuai
A16: 4 | B16: 001 | C16: Ayam Renald | D16: Restoran | E16: Tenant TikTok Food Fest, GBK, Jakarta | F16: Gelora | G16: Tanah Abang | H16: Kota Jakarta Pusat | I16: DKI Jakarta | J16: -6.2186 | K16: 106.8019 | L16: Titik tempat | M16: teks+inferensi | N16: Kawasan GBK Senayan | O16: Olahan ayam populer di media sosial | Q16: Ya | R16: 0.7 | S16: https://aktualita.co/ragam/tiktok-food-fest-2026-hari-terakhir-gbk | T16: aktualita.co | U16: TikTok Food Fest 2026 Hari Terakhir di GBK, Ada 40 Lebih Tenant hingga Kuliner Viral - Aktualita.co | V16: Aktualita.co | W16: 2026-09-27 | X16: Sesuai
A17: 4 | B17: 001 | C17: Aldi's Burger | D17: Restoran | E17: Tenant TikTok Food Fest, GBK, Jakarta | F17: Gelora | G17: Tanah Abang | H17: Kota Jakarta Pusat | I17: DKI Jakarta | J17: -6.2186 | K17: 106.8019 | L17: Titik tempat | M17: teks+inferensi | N17: Kawasan GBK Senayan | O17: Burger populer di media sosial | Q17: Ya | R17: 0.7 | S17: https://aktualita.co/ragam/tiktok-food-fest-2026-hari-terakhir-gbk | T17: aktualita.co | U17: TikTok Food Fest 2026 Hari Terakhir di GBK, Ada 40 Lebih Tenant hingga Kuliner Viral - Aktualita.co | V17: Aktualita.co | W17: 2026-09-27 | X17: Sesuai
A18: 5 | B18: 001 | C18: Sop Janda | D18: Restoran | E18: Jl. Raya Pekayon No. 11, Pekayon Jaya, Kec. Bekasi Selatan, Bekasi | F18: Pekayon Jaya | G18: Bekasi Selatan | H18: Kota Bekasi | I18: Jawa Barat | J18: -6.26 | K18: 106.988 | L18: Pusat kelurahan/desa | M18: teks+inferensi | O18: Perpaduan masakan Jawa-Sunda, sop janda daging dan sate maranggi, selalu ramai | Q18: Tidak | R18: 0.8 | S18: https://www.tripzilla.id/tempat-makan-di-bekasi-hits-legendaris-dan-ramah-kantong/27718 | T18: www.tripzilla.id | U18: Buat YTTA, Tempat Makan Di Bekasi Bikin Orang Jakarta Rela Antre! - tripzilla.id | V18: tripzilla.id | W18: 2026-09-22 | X18: Ragu
A19: 5 | B19: 001 | C19: Bebek Kaleyo | D19: Restoran | E19: Jl. Raya Kalimalang Kompleks Ruko Duta Permai, Bekasi | H19: Kota Bekasi | I19: Jawa Barat | J19: -6.238 | K19: 106.976 | L19: Pusat kota/kabupaten | M19: teks+inferensi | N19: Kawasan Kalimalang | O19: Bebek goreng renyah favorit keluarga | Q19: Tidak | R19: 0.85 | S19: https://www.tripzilla.id/tempat-makan-di-bekasi-hits-legendaris-dan-ramah-kantong/27718 | T19: www.tripzilla.id | U19: Buat YTTA, Tempat Makan Di Bekasi Bikin Orang Jakarta Rela Antre! - tripzilla.id | V19: tripzilla.id | W19: 2026-09-22 | X19: Ragu
A20: 5 | B20: 001 | C20: Fish n' Chops | D20: Restoran | E20: Jl. Boulevard Raya Ruko RGB No. 57-58, Jaka Setia, Bekasi | F20: Jaka Setia | G20: Bekasi Selatan | H20: Kota Bekasi | I20: Jawa Barat | J20: -6.268 | K20: 106.97 | L20: Pusat kelurahan/desa | M20: teks+inferensi | O20: Seafood platter krispi dengan harga bersahabat | Q20: Tidak | R20: 0.8 | S20: https://www.tripzilla.id/tempat-makan-di-bekasi-hits-legendaris-dan-ramah-kantong/27718 | T20: www.tripzilla.id | U20: Buat YTTA, Tempat Makan Di Bekasi Bikin Orang Jakarta Rela Antre! - tripzilla.id | V20: tripzilla.id | W20: 2026-09-22 | X20: Ragu
A21: 6 | B21: 001 | C21: Ayam Goreng Kalibogor | D21: Restoran | E21: Purwokerto, Banyumas | H21: Kabupaten Banyumas | I21: Jawa Tengah | J21: -7.45 | K21: 109.17 | L21: Pusat kota/kabupaten | M21: teks+inferensi | N21: Purwokerto (ibu kota Kab. Banyumas) | O21: Warung ayam goreng legendaris dengan resep rempah, ramai antrean | Q21: Tidak | R21: 0.75 | S21: https://jogja.disway.id/gaya-hidup/read/702022/deretan-warung-ayam-goreng-legendaris-paling-hits-di-purwokerto-dengan-cita-rasa-rempah | T21: jogja.disway.id | U21: Deretan Warung Ayam Goreng Legendaris Paling Hits di Purwokerto dengan Cita Rasa Rempah - jogja.disway.id - Disway Jogja | V21: Disway Jogja | W21: 2026-09-27 | X21: Sesuai
A22: 7 | B22: 001 | C22: Warung Amanda | D22: Restoran | E22: Jl. Raya Taman Pinang Indah No.6, Banjarbendo, Kec. Sidoarjo | F22: Banjarbendo | G22: Sidoarjo | H22: Kabupaten Sidoarjo | I22: Jawa Timur | J22: -7.439 | K22: 112.696 | L22: Pusat kelurahan/desa | M22: teks+inferensi | O22: Sego sambel lento khas Sidoarjo, buka 24 jam, harga murah | Q22: Tidak | R22: 0.85 | S22: https://jatim.idntimes.com/food/dining-guide/10-rekomendasi-kuliner-malam-di-sidoarjo-cocok-bagi-pencinta-kuliner-c1c2-01-njfwj-gnsrbz | T22: jatim.idntimes.com | U22: 10 Rekomendasi Kuliner Malam Sidoarjo, Gak Takut Lapar Saat Begadang - IDN Times Jatim | V22: IDN Times Jatim | W22: 2026-09-16 | X22: Sesuai
A23: 7 | B23: 001 | C23: Warung sego babat Jalan Diponegoro | D23: Restoran | E23: Jalan Diponegoro, Sidoarjo | G23: Sidoarjo | H23: Kabupaten Sidoarjo | I23: Jawa Timur | J23: -7.45 | K23: 112.715 | L23: Pusat kecamatan | M23: teks+inferensi | O23: Sego babat terkenal, selalu antre setiap malam, nasi empal | Q23: Tidak | R23: 0.6 | S23: https://jatim.idntimes.com/food/dining-guide/10-rekomendasi-kuliner-malam-di-sidoarjo-cocok-bagi-pencinta-kuliner-c1c2-01-njfwj-gnsrbz | T23: jatim.idntimes.com | U23: 10 Rekomendasi Kuliner Malam Sidoarjo, Gak Takut Lapar Saat Begadang - IDN Times Jatim | V23: IDN Times Jatim | W23: 2026-09-16 | X23: Sesuai
A24: 8 | B24: 001 | C24: Riung Tenda | D24: Restoran | E24: Jl. Balai Pustaka Timur No.2, Rawamangun, Pulo Gadung, Jakarta Timur | F24: Rawamangun | G24: Pulo Gadung | H24: Kota Jakarta Timur | I24: DKI Jakarta | J24: -6.196 | K24: 106.887 | L24: Pusat kelurahan/desa | M24: teks+inferensi | O24: Masakan Sunda murah, sambal dadak | Q24: Tidak | R24: 0.8 | S24: https://www.rumah123.com/explore/kota-jakarta-timur/tempat-makan-di-jakarta-timur-yang-murah-dan-enak/ | T24: www.rumah123.com | U24: 7 Rekomendasi Tempat Makan di Jakarta Timur yang Murah dan Enak - rumah123.com | V24: rumah123.com | W24: 2026-04-18 | X24: Sesuai
A25: 8 | B25: 001 | C25: Sari Idaman | D25: Restoran | E25: Jl. Cipinang Jaya Raya No.25A, Cipinang Muara, Jakarta Timur | F25: Cipinang Muara | G25: Jatinegara | H25: Kota Jakarta Timur | I25: DKI Jakarta | J25: -6.229 | K25: 106.892 | L25: Pusat kelurahan/desa | M25: teks+inferensi | O25: Menu Sunda, olahan gurame dan ayam goreng | Q25: Tidak | R25: 0.8 | S25: https://www.rumah123.com/explore/kota-jakarta-timur/tempat-makan-di-jakarta-timur-yang-murah-dan-enak/ | T25: www.rumah123.com | U25: 7 Rekomendasi Tempat Makan di Jakarta Timur yang Murah dan Enak - rumah123.com | V25: rumah123.com | W25: 2026-04-18 | X25: Sesuai
A26: 8 | B26: 001 | C26: Lesehan Gurame Pemuda | D26: Restoran | E26: Jl. Pemuda No.77, Rawamangun, Jakarta Timur | F26: Rawamangun | G26: Pulo Gadung | H26: Kota Jakarta Timur | I26: DKI Jakarta | J26: -6.196 | K26: 106.887 | L26: Pusat kelurahan/desa | M26: teks+inferensi | O26: Olahan gurame dan seafood konsep lesehan | Q26: Tidak | R26: 0.8 | S26: https://www.rumah123.com/explore/kota-jakarta-timur/tempat-makan-di-jakarta-timur-yang-murah-dan-enak/ | T26: www.rumah123.com | U26: 7 Rekomendasi Tempat Makan di Jakarta Timur yang Murah dan Enak - rumah123.com | V26: rumah123.com | W26: 2026-04-18 | X26: Sesuai
A27: 8 | B27: 001 | C27: Sambal Bakar Indonesia | D27: Restoran | E27: Jl. Lingkar Duren Sawit No.3, Duren Sawit, Jakarta Timur | G27: Duren Sawit | H27: Kota Jakarta Timur | I27: DKI Jakarta | J27: -6.23 | K27: 106.915 | L27: Pusat kecamatan | M27: teks+inferensi | O27: Sedang populer dengan konsep sambal bakar unik | Q27: Tidak | R27: 0.8 | S27: https://www.rumah123.com/explore/kota-jakarta-timur/tempat-makan-di-jakarta-timur-yang-murah-dan-enak/ | T27: www.rumah123.com | U27: 7 Rekomendasi Tempat Makan di Jakarta Timur yang Murah dan Enak - rumah123.com | V27: rumah123.com | W27: 2026-04-18 | X27: Sesuai
A28: 8 | B28: 001 | C28: Teras Rumah Nenek | D28: Kafe | E28: Jl. Abdulrahman No.46, Cibubur, Ciracas, Jakarta Timur | F28: Cibubur | G28: Ciracas | H28: Kota Jakarta Timur | I28: DKI Jakarta | J28: -6.364 | K28: 106.883 | L28: Pusat kelurahan/desa | M28: teks+inferensi | O28: Tempat makan sekaligus kafe asri dengan area outdoor luas | Q28: Tidak | R28: 0.8 | S28: https://www.rumah123.com/explore/kota-jakarta-timur/tempat-makan-di-jakarta-timur-yang-murah-dan-enak/ | T28: www.rumah123.com | U28: 7 Rekomendasi Tempat Makan di Jakarta Timur yang Murah dan Enak - rumah123.com | V28: rumah123.com | W28: 2026-04-18 | X28: Sesuai
A29: 9 | B29: 001 | C29: Bakso President | D29: Restoran | E29: Malang | H29: Kota Malang | I29: Jawa Timur | J29: -7.98 | K29: 112.63 | L29: Pusat kota/kabupaten | M29: teks+inferensi | N29: Malang diasumsikan Kota Malang | O29: Bakso legendaris sejak 1977 di sisi rel kereta api aktif | Q29: Tidak | R29: 0.9 | S29: https://erafone.com/artikel/post/wisata-kuliner-malang-04 | T29: erafone.com | U29: 10 Rekomendasi Destinasi Wisata Kuliner Malang yang Enak - Erafone | V29: Erafone | W29: 2026-08-18 | X29: Sesuai
A30: 9 | B30: 001 | C30: Rawon Nguling | D30: Restoran | E30: Malang | H30: Kota Malang | I30: Jawa Timur | J30: -7.98 | K30: 112.63 | L30: Pusat kota/kabupaten | M30: teks+inferensi | N30: Malang diasumsikan Kota Malang | O30: Rawon khas Jawa Timur sejak 1980-an, kuah kluwek | Q30: Tidak | R30: 0.85 | S30: https://erafone.com/artikel/post/wisata-kuliner-malang-04 | T30: erafone.com | U30: 10 Rekomendasi Destinasi Wisata Kuliner Malang yang Enak - Erafone | V30: Erafone | W30: 2026-08-18 | X30: Sesuai
A31: 9 | B31: 001 | C31: Depot Hok Lay | D31: Restoran | E31: Malang | H31: Kota Malang | I31: Jawa Timur | J31: -7.98 | K31: 112.63 | L31: Pusat kota/kabupaten | M31: teks+inferensi | N31: Malang diasumsikan Kota Malang | O31: Destinasi kuliner legendaris Malang | Q31: Tidak | R31: 0.8 | S31: https://erafone.com/artikel/post/wisata-kuliner-malang-04 | T31: erafone.com | U31: 10 Rekomendasi Destinasi Wisata Kuliner Malang yang Enak - Erafone | V31: Erafone | W31: 2026-08-18 | X31: Sesuai
A32: 10 | B32: 001 | C32: Laksa Pak Masitar | D32: Restoran | E32: Tangerang | I32: Banten | J32: -6.405 | K32: 106.064 | L32: Pusat provinsi | M32: teks+inferensi | N32: Tangerang ambigu (Kota/Kabupaten Tangerang) | O32: Laksa khas Tangerang legendaris, berjualan 36 tahun | Q32: Tidak | R32: 0.8 | S32: https://www.hipwee.com/travel/tempat-makan-murah-di-tangerang/ | T32: www.hipwee.com | U32: 8 Tempat Makan Murah di Tangerang yang Enak dan Bikin Kenyang - Hipwee | V32: Hipwee | W32: 2026-07-22 | X32: Sesuai
A33: 10 | B33: 001 | C33: Warung Bogana May-May | D33: Restoran | E33: Pasar Modern BSD, Tangerang Selatan | F33: Lengkong Gudang | G33: Serpong | H33: Kota Tangerang Selatan | I33: Banten | J33: -6.302 | K33: 106.68 | L33: Pusat kelurahan/desa | M33: teks+inferensi | N33: Pasar Modern BSD | O33: Nasi bogana dengan isian lengkap, murah | Q33: Tidak | R33: 0.8 | S33: https://www.hipwee.com/travel/tempat-makan-murah-di-tangerang/ | T33: www.hipwee.com | U33: 8 Tempat Makan Murah di Tangerang yang Enak dan Bikin Kenyang - Hipwee | V33: Hipwee | W33: 2026-07-22 | X33: Sesuai
A34: 11 | B34: 001 | C34: Harmadha Joglo | D34: Restoran | E34: Jl. Diponegoro No. 21, Nganten, Selosari, Kecamatan Magetan, Kabupaten Magetan | F34: Selosari | G34: Magetan | H34: Kabupaten Magetan | I34: Jawa Timur | J34: -7.65 | K34: 111.33 | L34: Pusat kelurahan/desa | M34: teks+inferensi | O34: Restoran dan kafe hits, sop iga dan rawon | Q34: Tidak | R34: 0.9 | S34: https://rri.co.id/madiun/kuliner/2758486/harmadha-joglo-tempat-kuliner-hits-magetan | T34: rri.co.id | U34: Harmadha Joglo, Tempat Kuliner Hits Magetan - RRI.co.id | V34: RRI.co.id | W34: 2026-09-25 | X34: Sesuai
A35: 12 | B35: 001 | C35: RM Mang Iki | D35: Restoran | E35: Jl. Pasar Baru No. 84, Ciwalen, Garut Kota, Garut | F35: Ciwalen | G35: Garut Kota | H35: Kabupaten Garut | I35: Jawa Barat | J35: -7.213 | K35: 107.905 | L35: Pusat kelurahan/desa | M35: teks+inferensi | O35: Rumah makan Sunda legendaris sejak 1970 | Q35: Tidak | R35: 0.9 | S35: https://food.detik.com/tempat-makan/d-8549503/7-tempat-makan-di-garut-yang-enak-dan-murah-favorit-warga-lokal | T35: food.detik.com | U35: 7 Tempat Makan di Garut yang Enak dan Murah, Favorit Warga Lokal - detikFood | V35: detikFood | W35: 2026-06-27 | X35: Sesuai
A36: 12 | B36: 001 | C36: RM Saung Cikenceh | D36: Restoran | E36: Garut Kota, Garut | G36: Garut Kota | H36: Kabupaten Garut | I36: Jawa Barat | J36: -7.215 | K36: 107.9 | L36: Pusat kecamatan | M36: teks+inferensi | O36: Hidangan Sunda autentik, suasana santai, harga terjangkau | Q36: Tidak | R36: 0.85 | S36: https://food.detik.com/tempat-makan/d-8549503/7-tempat-makan-di-garut-yang-enak-dan-murah-favorit-warga-lokal | T36: food.detik.com | U36: 7 Tempat Makan di Garut yang Enak dan Murah, Favorit Warga Lokal - detikFood | V36: detikFood | W36: 2026-06-27 | X36: Sesuai
A37: 13 | B37: 001 | C37: Ayam Bakar Christina (ABC) | D37: Restoran | E37: Jl. Margonda Raya No. 420, Pondok Cina, Beji, Depok | F37: Pondok Cina | G37: Beji | H37: Kota Depok | I37: Jawa Barat | J37: -6.37 | K37: 106.83 | L37: Pusat kelurahan/desa | M37: teks+inferensi | O37: Ayam bakar legendaris sejak 1986 | Q37: Tidak | R37: 0.9 | S37: https://www.tripzilla.id/tempat-makan-di-depok/27073 | T37: www.tripzilla.id | U37: 🍽️ [Paling Update] 30+ Tempat Makan di Depok Untuk Pecinta Kuliner! - tripzilla.id | V37: tripzilla.id | W37: 2026-05-21 | X37: Sesuai
A38: 13 | B38: 001 | C38: Rumah Makan Gandy | D38: Restoran | E38: Jl. Raya Muchtar No. 24, Bojongsari, Sawangan, Depok | G38: Sawangan | H38: Kota Depok | I38: Jawa Barat | J38: -6.4 | K38: 106.765 | L38: Pusat kecamatan | M38: teks+inferensi | N38: Bojongsari kini kecamatan tersendiri (pemekaran dari Sawangan); kelurahan ambigu | O38: Masakan Betawi-Sunda sejak era 70-an, pecak gurame | Q38: Tidak | R38: 0.85 | S38: https://www.tripzilla.id/tempat-makan-di-depok/27073 | T38: www.tripzilla.id | U38: 🍽️ [Paling Update] 30+ Tempat Makan di Depok Untuk Pecinta Kuliner! - tripzilla.id | V38: tripzilla.id | W38: 2026-05-21 | X38: Sesuai
A39: 13 | B39: 001 | C39: Nasi Uduk H. Yoyo | D39: Restoran | E39: Depok | H39: Kota Depok | I39: Jawa Barat | J39: -6.402 | K39: 106.795 | L39: Pusat kota/kabupaten | M39: teks+inferensi | O39: Salah satu destinasi kuliner tertua di Depok, 60+ tahun | Q39: Tidak | R39: 0.8 | S39: https://www.tripzilla.id/tempat-makan-di-depok/27073 | T39: www.tripzilla.id | U39: 🍽️ [Paling Update] 30+ Tempat Makan di Depok Untuk Pecinta Kuliner! - tripzilla.id | V39: tripzilla.id | W39: 2026-05-21 | X39: Sesuai
A40: 14 | B40: 001 | C40: RM Salam Sereh | D40: Restoran | E40: Jl. Raya Kp. Sawah, Bojong, Kec. Kemang, Kab. Bogor | F40: Bojong | G40: Kemang | H40: Kabupaten Bogor | I40: Jawa Barat | J40: -6.504 | K40: 106.745 | L40: Pusat kecamatan | M40: teks+inferensi | O40: Restoran baru Sunda di tengah persawahan | P40: Juni 2026 | Q40: Tidak | R40: 0.85 | S40: https://www.nibble.id/restoran-baru-di-bogor-juni-2026/ | T40: www.nibble.id | U40: 10 Restoran Baru di Bogor Juni 2026 - nibble.id | V40: nibble.id | W40: 2026-06-07 | X40: Sesuai
...

Sheet Artikel
A1: article_id | B1: batch | C1: jumlah_tempat | D1: jumlah_viral_eksplisit | E1: final_url (sumber isi) | F1: domain URL | G1: judul (id_map) | H1: source (id_map) | I1: published (id_map) | J1: cuplikan isi | K1: judul sesuai isi? | L1: skor judul vs isi | M1: skor URL vs isi
A2: 0 | B2: 001 | C2: 0 | D2: 0 | E2: https://jatimnet.com/media-sosial-mengubah-cara-kita-memilih-tempat-makan | F2: jatimnet.com | G2: Media Sosial Mengubah Cara Kita Memilih Tempat Makan - Jatimnet.com | H2: Jatimnet.com | I2: 2026-09-25 | J2: Jumat, 25 September 2026 08:00 UTC Ilustrasi: Pilihan dari Layar. -Dx Gen-AI JATIMNET.COM - Media sosial mengubah cara memilih tempat makan dalam kehidupan sehari-hari. Restoran yang sebelumnya ditemu | K2: Sesuai | L2: 0.88 | M2: 0.88
A3: 1 | B3: 001 | C3: 4 | D3: 0 | E3: https://food.detik.com/rumah-makan/d-8679688/awas-kalap-ini-7-tempat-makan-soto-mie-legendaris-di-jakarta-dan-bogor | F3: food.detik.com | G3: Awas Kalap! Ini 7 Tempat Makan Soto Mie Legendaris di Jakarta dan Bogor - detikFood | H3: detikFood | I3: 2026-09-26 | J3: Di Jakarta dan Bogor, ada kedai soto mie yang sudah buka sejak puluhan tahun lalu dan terkenal lezat. Bahkan sampai sekarang masih terus diburu oleh pelanggannya. Soto mie menjadi salah satu hidangan | K3: Sesuai | L3: 0.67 | M3: 0.6
A4: 2 | B4: 001 | C4: 2 | D4: 0 | E4: https://rri.co.id/yogyakarta/kuliner/2752639/rekomendasi-7-tempat-makan-ramah-kantong-di-jogja-dan-tips-menggunakan-grabfood | F4: rri.co.id | G4: Rekomendasi 7 Tempat Makan Ramah Kantong di Jogja dan Tips Menggunakan GrabFood - RRI.co.id | H4: RRI.co.id | I4: 2026-09-23 | J4: RRI.CO.ID, Yogyakarta - Daerah Istimewa Yogyakarta (DIY).dikenal luas sebagai surganya kuliner murah di Indonesia, tempat menikmati hidangan otentik Jawa hingga sajian internasional tanpa menguras dom | K4: Sesuai | L4: 0.78 | M4: 0.82
A5: 3 | B5: 001 | C5: 2 | D5: 2 | E5: https://www.nibble.id/tempat-makan-viral-di-bandung-2026/ | F5: www.nibble.id | G5: 10 Tempat Makan Viral di Bandung 2026 - nibble.id | H5: nibble.id | I5: 2026-06-09 | J5: Harus siapkan mental buat antre, ini dia tempat makan viral di Bandung 2026 yang sampai kini selalu gak ada habisnya dibahas. Kota ini memang gak ada hentinya untuk memunculkan banyak spot kulineran e | K5: Sesuai | L5: 1 | M5: 1
A6: 4 | B6: 001 | C6: 8 | D6: 8 | E6: https://aktualita.co/ragam/tiktok-food-fest-2026-hari-terakhir-gbk | F6: aktualita.co | G6: TikTok Food Fest 2026 Hari Terakhir di GBK, Ada 40 Lebih Tenant hingga Kuliner Viral - Aktualita.co | H6: Aktualita.co | I6: 2026-09-27 | J6: English edition available TikTok Food Fest 2026 Hari Terakhir di GBK, Ada 40 Lebih Tenant hingga Kuliner Viral Jakarta , Aktualita.co — TikTok Food Fest 2026 memasuki hari terakhir penyelenggaraan pad | K6: Sesuai | L6: 1 | M6: 0.86
A7: 5 | B7: 001 | C7: 3 | D7: 0 | E7: https://www.tripzilla.id/tempat-makan-di-bekasi-hits-legendaris-dan-ramah-kantong/27718 | F7: www.tripzilla.id | G7: Buat YTTA, Tempat Makan Di Bekasi Bikin Orang Jakarta Rela Antre! - tripzilla.id | H7: tripzilla.id | I7: 2026-09-22 | J7: Sebagai seorang travel writer yang hobi keliling berburu kuliner, Bekasi sering kali mengejutkan saya! Kota yang sering dituduh "berada di luar planet" ini ternyata menyimpan surga kuliner yang sangat | K7: Ragu | L7: 0.44 | M7: 0.43
A8: 6 | B8: 001 | C8: 1 | D8: 0 | E8: https://jogja.disway.id/gaya-hidup/read/702022/deretan-warung-ayam-goreng-legendaris-paling-hits-di-purwokerto-dengan-cita-rasa-rempah | F8: jogja.disway.id | G8: Deretan Warung Ayam Goreng Legendaris Paling Hits di Purwokerto dengan Cita Rasa Rempah - jogja.disway.id - Disway Jogja | H8: Disway Jogja | I8: 2026-09-27 | J8: Ayam Goreng Kalibogor-- diswayjogja.id - Dunia kuliner tradisional di Kota Purwokerto terus menunjukkan pesona yang sangat kuat dan memukau, ditandai dengan tetap eksisnya berbagai warung serta rumah | K8: Sesuai | L8: 0.62 | M8: 0.77
A9: 7 | B9: 001 | C9: 2 | D9: 0 | E9: https://jatim.idntimes.com/food/dining-guide/10-rekomendasi-kuliner-malam-di-sidoarjo-cocok-bagi-pencinta-kuliner-c1c2-01-njfwj-gnsrbz | F9: jatim.idntimes.com | G9: 10 Rekomendasi Kuliner Malam Sidoarjo, Gak Takut Lapar Saat Begadang - IDN Times Jatim | H9: IDN Times Jatim | I9: 2026-09-16 | J9: Kuliner malam di Sidoarjo menjadi daya tarik tersendiri bagi masyarakat Jawa Timur. Berbagai warung makan, kaki lima, hingga restoran tetap ramai dikunjungi saat malam hari. Perpaduan antara sajian ya | K9: Sesuai | L9: 0.5 | M9: 0.46
A10: 8 | B10: 001 | C10: 5 | D10: 0 | E10: https://www.rumah123.com/explore/kota-jakarta-timur/tempat-makan-di-jakarta-timur-yang-murah-dan-enak/ | F10: www.rumah123.com | G10: 7 Rekomendasi Tempat Makan di Jakarta Timur yang Murah dan Enak - rumah123.com | H10: rumah123.com | I10: 2026-04-18 | J10: Mencari tempat makan di Jakarta Timur yang murah dan enak bukan hal sulit. Kawasan ini punya banyak pilihan, mulai dari warung sederhana hingga restoran keluarga dengan harga yang masih ramah di kanto | K10: Sesuai | L10: 1 | M10: 0.75
A11: 9 | B11: 001 | C11: 3 | D11: 0 | E11: https://erafone.com/artikel/post/wisata-kuliner-malang-04 | F11: erafone.com | G11: 10 Rekomendasi Destinasi Wisata Kuliner Malang yang Enak - Erafone | H11: Erafone | I11: 2026-08-18 | J11: Malang tidak hanya terkenal dengan deretan tempat wisata dan lingkungan udaranya yang sejuk. Kota ini juga punya surga kuliner yang akan memanjakan perut kamu, mulai dari bakso legendaris, rawon denga | K11: Sesuai | L11: 1 | M11: 1
A12: 10 | B12: 001 | C12: 2 | D12: 0 | E12: https://www.hipwee.com/travel/tempat-makan-murah-di-tangerang/ | F12: www.hipwee.com | G12: 8 Tempat Makan Murah di Tangerang yang Enak dan Bikin Kenyang - Hipwee | H12: Hipwee | I12: 2026-07-22 | J12: Berburu tempat makan di Tangerang sebenarnya nggak terlalu sulit karena pilihannya melimpah. Mulai dari area Pasar Lama yang padat kuliner legendaris sampai sudut-sudut BSD, selalu ada pilihan tempat | K12: Sesuai | L12: 0.71 | M12: 0.8
A13: 11 | B13: 001 | C13: 1 | D13: 0 | E13: https://rri.co.id/madiun/kuliner/2758486/harmadha-joglo-tempat-kuliner-hits-magetan | F13: rri.co.id | G13: Harmadha Joglo, Tempat Kuliner Hits Magetan - RRI.co.id | H13: RRI.co.id | I13: 2026-09-25 | J13: RRI.CO.ID, Madiun - Siapa sih yang tidak kenal Harmadha Joglo? Salah satu restoran sekaligus tempat nongkrong yang cukup terkenal di Magetan ini selalu menjadi pilihan bagi masyarakat yang ingin menik | K13: Sesuai | L13: 0.83 | M13: 0.86
... A75: 73 | B75: 003 | C75: 0 | D75: 0 | E75: https://gotvnews.co.id/viral-kasatpol-pp-samarinda-cekcok-dengan-anggota-tni-saat-penertiban-warung-miras/ | F75: gotvnews.co.id | G75: Viral, Kasatpol PP Samarinda Cekcok Dengan Anggota TNI Saat Penertiban Warung Miras - gotvnews.co.id | H75: gotvnews.co.id | I75: 2026-09-24 | J75: GOTVNEWS, Kaltim – Penertiban sejumlah warung yang diduga menjadi lokasi penjualan minuman keras di Jalan Teuku Umar, Samarinda, Kalimantan Timur, Selasa (22/9/2026) malam, sempat diwarnai cekcok anta | K75: Sesuai | L75: 0.75 | M75: 0.75
A76: 74 | B76: 003 | C76: 0 | D76: 0 | E76: https://www.mcwnews.com | F76: www.mcwnews.com | G76: Duo WN Iran Viral Hipnotis Pedagang Warung Ditangkap di Kuta - mcwnews.com | H76: mcwnews.com | I76: 2026-09-22 | J76: Kejari Mimika Tetapkan Tersangka Korupsi Pembangunan Gerai Maritim Kejagung Tetapkan 5 Tersangka Korupsi Tata Kelola Nikel, Kerugian Negara Rp401,65 Miliar DPO Korupsi Kejati Kalsel Ditangkap di Berau | K76: Tidak sesuai | L76: 0.14
A77: 75 | B77: 003 | C77: 0 | D77: 0 | E77: https://radarbadung.jawapos.com/bali/2609160004/ngaku-pecalang-pungut-rp120-ribu-di-warung-warga-gianyar-viral-di-tiktok | F77: radarbadung.jawapos.com | G77: Ngaku Pecalang Pungut Rp120 Ribu di Warung, Warga Gianyar Viral di TikTok - Radar Badung | H77: Radar Badung | I77: 2026-09-16 | J77: Aksi pria mengaku sebagai Pecalang dan meminta uang keamanan serta iuran banjar di sebuah warung makan di Jalan Gunung Soputan, Denpasar, viral di media sosial TikTok. | K77: Ragu | L77: 0.33 | M77: 0.3
A78: 76 | B78: 003 | C78: 0 | D78: 0 | E78: https://news.detik.com/berita/d-8643188/viral-pemotor-dikejar-begal-sampai-nabrak-warung-di-tebet-polisi-selidiki | F78: news.detik.com | G78: Viral Pemotor Dikejar Begal Sampai Nabrak Warung di Tebet, Polisi Selidiki - detikNews | H78: detikNews | I78: 2026-09-01 | J78: Rekaman CCTV yang menunjukkan dugaan pembegalan terhadap dua orang pemuda di Tebet, Jakarta Selatan (Jaksel), viral di media sosial. Polisi menduga korban dan pelaku diduga saling kenal. Dalam video y | K78: Sesuai | L78: 0.56 | M78: 0.56
A79: 77 | B79: 003 | C79: 0 | D79: 0 | E79: https://depok.tribunnews.com/news/52323/viral-penyerangan-pelajar-di-duren-sawit-korban-ditebas-sajam-warung-jadi-sasaran-amuk-pelaku | F79: depok.tribunnews.com | G79: Viral Penyerangan Pelajar di Duren Sawit: Korban Ditebas Sajam, Warung Jadi Sasaran Amuk Pelaku - Tribunnewsdepok.com | H79: Tribunnewsdepok.com | I79: 2026-09-13 | J79: Belum punya akun? Daftar Akun Download TribunX untuk Android & iOS TRIBUNNEWSDEPOK.COM, JAKARTA TIMUR – Jagat media sosial dihebohkan oleh rekaman video aksi penyerangan brutal sekelompok pelajar berm | K79: Sesuai | L79: 0.73 | M79: 0.73
A80: 78 | B80: 003 | C80: 0 | D80: 0 | E80: https://www.suryaindonesia.net/2026/09/10/viral-di-media-sosial-terkait-dugaan-aksi-penipuan-yang-melibatkan-seorang-warga-negara-asing-wna-di-sebuah-warung-wilayah-darmasaba/ | F80: www.suryaindonesia.net | G80: Viral di Media Sosial terkait dugaan aksi penipuan yang melibatkan seorang warga negara asing (WNA) di sebuah warung wilayah Darmasaba - suryaindonesia.net | H80: suryaindonesia.net | I80: 2026-09-10 | J80: Redaksi Surya Indonesia Kamis, 10 September 2026 - 16:18 WIB Mangupura, Surya Indonesia.net – Menindaklanjuti informasi yang Viral di Media Sosial terkait dugaan aksi penipuan yang melibatka | K80: Sesuai | L80: 1 | M80: 1
A81: 79 | B81: 003 | C81: 1 | D81: 1 | E81: https://carapandang.com/news/read/warung-di-tengah-makam-viral-ulama-tegaskan-kuburan-muslim-harus-dijaga-kehormatannya | F81: carapandang.com | G81: Warung di Tengah Makam Viral, Ulama Tegaskan Kuburan Muslim Harus Dijaga Kehormatannya - CaraPandang | H81: CaraPandang | I81: 2026-07-24 | J81: CARAPANDANG – Sebuah warung makan yang berdiri di tengah kompleks pemakaman di Karawang, Jawa Barat, menjadi perhatian publik. Lokasinya yang tidak lazim membuat banyak orang penasaran hingga rela dat | K81: Ragu | L81: 0.4 | M81: 0.4
A82: 80 | B82: 003 | C82: 1 | D82: 1 | E82: https://regional.kompas.com/read/2026/07/17/183019078/viral-warung-lontong-di-pati-ditarik-retribusi-rp-840000-dputr-bukan-tarif?page=all | F82: regional.kompas.com | G82: Viral Warung Lontong di Pati Ditarik Retribusi Rp 840.000, DPUTR: Bukan Tarif Setahun - Kompas.com | H82: Kompas.com | I82: 2026-07-17 | J82: Viral Warung Lontong di Pati Ditarik Retribusi Rp 840.000, DPUTR: Bukan Tarif Setahun PATI, KOMPAS.com – Video seorang pemilik warung lontong sayur di Desa Kebolampang, Kecamatan Winong, Kabupaten Pat | K82: Sesuai | L82: 1 | M82: 1
A83: 81 | B83: 003 | C83: 1 | D83: 0 | E83: https://timesindonesia.co.id/kuliner/601107/tidak-viral-tapi-warung-ini-punya-menu-andalan-yang-bikin-pelanggan-rela-balik-lagi | F83: timesindonesia.co.id | G83: Tidak Viral, Tapi Warung ini Punya Menu Andalan yang Bikin Pelanggan Rela Balik Lagi - TIMES Indonesia | H83: TIMES Indonesia | I83: 2026-07-28 | J83: BATU – Di tengah menjamurnya tempat kuliner dengan konsep kekinian, sebuah warung sederhana di Kota Batu justru mencuri perhatian lewat cara berbeda. Tidak mengandalkan promosi besar di media sosial, | K83: Ragu | L83: 0.45 | M83: 0.5
A84: 82 | B84: 003 | C84: 0 | D84: 0 | E84: https://gotvnews.co.id/viral-dua-pria-terlibat-perkelahian-di-warung-kopi-tanjungpinang-diduga-berawal-saling-senggol/ | F84: gotvnews.co.id | G84: Viral! Dua Pria Terlibat Perkelahian di Warung Kopi Tanjungpinang, Diduga Berawal Saling Senggol - gotvnews.co.id | H84: gotvnews.co.id | I84: 2026-09-21 | J84: GOTVNEWS, Tanjungpinang – Video dua pria terlibat perkelahian di sebuah warung kopi di kawasan Bakar Batu, Kota Tanjungpinang, viral di media sosial, Senin (21/9/2026). Dalam video yang beredar, seora | K84: Sesuai | L84: 0.91 | M84: 0.91
A85: 83 | B85: 003 | C85: 1 | D85: 1 | E85: https://food.detik.com/info-kuliner/d-8649807/viral-bebi-romeo-hobi-makan-mie-ayam-warung-makan-ini-jadi-favorit | F85: food.detik.com | G85: Viral! Bebi Romeo Hobi Makan Mie Ayam, Warung Makan Ini Jadi Favorit - detikFood | H85: detikFood | I85: 2026-09-05 | J85: Bebi Romeo diketahui hobi membagikan momen saat menikmati mie ayam favoritnya di kawasan Fatmawati, Jakarta Selatan. Berikut nama warung makan dan racikan favoritnya! Mie ayam memang digemari banyak o | K85: Sesuai | L85: 1 | M85: 0.8
A86: 84 | B86: 003 | C86: 0 | D86: 0 | E86: https://news.detik.com/berita/d-8577814/bang-jago-bersajam-viral-bikin-onar-di-warung-jamu-bogor-ditangkap | F86: news.detik.com | G86: Bang Jago Bersajam Viral Bikin Onar di Warung Jamu Bogor Ditangkap - detikNews | H86: detikNews | I86: 2026-07-17 | J86: Pria yang membawa golok dan membuat onar di warung jamu kawasan Kamurang, Kecamatan Citeureup, Bogor , Jawa Barat, ditangkap. Pelaku berinisial IK (18). "Polsek Citeureup bersama Tim Resmob Polres Bog | K86: Sesuai | L86: 0.89 | M86: 0.89
A87: 85 | B87: 003 | C87: 0 | D87: 0 | E87: https://20.detik.com/detikupdate/20260730-260730011/video-viral-sekelompok-pemuda-bawa-celurit-serang-warung-makan-di-sidoarjo | F87: 20.detik.com | G87: Video Viral Sekelompok Pemuda Bawa Celurit Serang Warung Makan di Sidoarjo - 20detik | H87: 20detik | I87: 2026-07-30 | J87: Scroll atau gunakan tombol [ ] [ ] serta klik panah di sisi kanan untuk menjelajahi feed video. Viral sekelompok pemud | K87: Sesuai | L87: 0.56 | M87: 0.5
A88: 86 | B88: 003 | C88: 0 | D88: 0 | E88: https://news.detik.com/berita/d-8573022/viral-bang-jago-bersajam-bikin-onar-di-warung-jamu-bogor-polisi-selidiki | F88: news.detik.com | G88: Viral Bang Jago Bersajam Bikin Onar di Warung Jamu Bogor, Polisi Selidiki - detikNews | H88: detikNews | I88: 2026-07-14 | J88: Video seorang pria membuat onar di sebuah warung jamu kawasan Kamurang, Kecamatan Citeureup, Bogor , Jawa Barat, beredar di media sosial. Pria tersebut tampak membawa senjata tajam. Dalam video yang d | K88: Sesuai | L88: 0.6 | M88: 0.6
... A140: 138 | B140: 005 | C140: 1 | D140: 0 | E140: https://swa.co.id/read/471273/destinasi-wisata-baru-di-jogja-ini-6-hal-yang-ditawarkan-di-ibarbo-park | F140: swa.co.id | G140: Destinasi Wisata Baru di Jogja, Ini 6 Hal yang Ditawarkan Di Ibarbo Park! - SWA.co.id | H140: SWA.co.id | I140: 2026-04-10 | J140: Dilarang keras mengambil konten (tulisan, foto, infografis, video, dan sebagainya) yang dimuat di situs web ini, melakukan crawling atau pengindeksan otomatis untuk p | K140: Tidak sesuai | L140: 0 | M140: 0
A141: 139 | B141: 005 | C141: 1 | D141: 1 | E141: https://nativeindonesia.com/mikutopia-batu/ | F141: nativeindonesia.com | G141: Mikutopia Batu, Surga Wisata Baru yang Lagi Viral di Malang - NativeIndonesia.com | H141: NativeIndonesia.com | I141: 2026-04-03 | J141: Nativeindonesia – Popularitas Mikutopia Batu semakin melejit berkat media sosial. Banyak pengunjung yang membagikan momen seru mereka saat berada di lokasi ini, mulai dari spot foto yang estetik hingg | K141: Sesuai | L141: 0.83
A142: 140 | B142: 005 | C142: 4 | D142: 4 | E142: https://chanelmuslim.com/wisata/viral-canyoning-banyak-digemari-kalangan-muda-dan-jadi-destinasi-baru-di-bogor | F142: chanelmuslim.com | G142: Viral, Canyoning Banyak Digemari Kalangan Muda dan Jadi Destinasi Baru di Bogor - Chanelmuslim.com | H142: Chanelmuslim.com | I142: 2026-08-24 | J142: <strong>BOGOR</strong> kembali menghadirkan destinasi wisata baru yang tengah viral di kalangan muda, yakni Canyoning Bogor. Aktivitas ekstrem yang memadukan petualangan alam dan olahraga ini kini men | K142: Sesuai | L142: 1 | M142: 1
A143: 141 | B143: 005 | C143: 6 | D143: 1 | E143: https://radarsukabumi.com/wisata/10-tempat-wisata-hits-di-sukabumi-2026-yang-wajib-masuk-bucket-list-kamu/ | F143: radarsukabumi.com | G143: 10 Tempat Wisata Hits di Sukabumi 2026 yang Wajib Masuk Bucket List Kamu! - radarsukabumi.com | H143: radarsukabumi.com | I143: 2026-06-20 | J143: Biar kalian nggak kudet, yuk simak 10 tempat wisata favorit di Sukabumi terbaru tahun 2026 yang wajib kalian datangi bareng geng atau pacar: 1. Goalpara Tea Park (GTP) Bukan cuma kebun teh biasa, temp | K143: Sesuai | L143: 0.56 | M143: 0.56
A144: 142 | B144: 005 | C144: 1 | D144: 1 | E144: https://www.detik.com/jatim/wisata/d-8429886/5-fakta-uji-coba-berbahaya-mikutopia-pengunjung-tewas-wahana-patah | F144: www.detik.com | G144: 5 Fakta Uji Coba Berbahaya Mikutopia: Pengunjung Tewas-Wahana Patah - detikcom | H144: detikcom | I144: 2026-04-05 | J144: Destinasi wisata baru Mikutopia di Kecamatan Bumiaji, Kota Batu, mendadak viral. Namun bukan karena keindahan atau daya tariknya, melainkan serangkaian insiden yang memicu kekhawatiran publik. Dalam w | K144: Sesuai | L144: 0.78 | M144: 0.73
A145: 143 | B145: 005 | C145: 1 | D145: 1 | E145: https://tv.sinpo.id/detail/museum-anti-stres-viral-di-china | F145: tv.sinpo.id | G145: Museum Anti Stres Viral di China - SinPo.id | H145: SinPo.id | I145: 2026-06-09 | J145: SinPo.tv - Sebuah museum unik di Kota Shenzhen, China, menarik perhatian pengunjung dengan berbagai instalasi seni nyeleneh yang menyindir tekanan hidup modern dan budaya kerja saat ini. 30 Agustus 20 | K145: Sesuai | L145: 0.5 | M145: 0.5
A146: 144 | B146: 005 | C146: 1 | D146: 1 | E146: https://jogja.times.co.id/news/wisata/YF3oMMsA/gratis-plus-viral-museum-terumbu-karang-indonesia-sajikan-pesona-bawah-laut | F146: jogja.times.co.id | G146: Gratis plus Viral, Museum Terumbu Karang Indonesia Sajikan Pesona Bawah Laut - TIMES Jogja | H146: TIMES Jogja | I146: 2026-07-10 | J146: Museum Terumbu Karang Indonesia menawarkan pengalaman menjelajahi ekosistem laut Indonesia tanpa harus basah-basahan. JOGJA – Siapa bilang menikmati keindahan bawah laut harus pergi ke pantai atau men | K146: Sesuai | L146: 0.8 | M146: 0.75
A147: 145 | B147: 005 | C147: 0 | D147: 0 | E147: https://jogja.disway.id/wisata/read/700045/cara-baru-keliling-museum-dengan-koleksi-cap-estetik-dengan-museum-passport-yang-viral | F147: jogja.disway.id | G147: Cara Baru Keliling Museum dengan Koleksi Cap Estetik dengan Museum Passport yang Viral - jogja.disway.id - Disway Jogja | H147: Disway Jogja | I147: 2026-07-01 | J147: Museum Passport yang Viral-- diswayjogja.id - Bagi banyak orang, mengunjungi museum mungkin dianggap sebagai kegiatan yang monoton dan kaku. Namun, narasi tersebut perlahan berubah sejak kehadiran Mus | K147: Ragu | L147: 0.44 | M147: 0.62
A148: 146 | B148: 005 | C148: 1 | D148: 1 | E148: https://mimbarrakyatnews.com/art-dialogue-ii-viral-dan-antrean-panjang-di-tasikmalaya-galeri-belum-buka-kang-acong-monolog/ | F148: mimbarrakyatnews.com | G148: Art dialogue II viral dan antrean panjang di Tasikmalaya: galeri belum buka, kang acong monolog - mimbarrakyatnews.com | H148: mimbarrakyatnews.com | I148: 2026-08-01 | J148: Antrean panjang sudah mengular di depan galeri sebelum pintu resmi dibuka untuk Art Dialogue II di Tasikmalaya , sebuah kejadian yang jadi bahan perbincangan setelah video singkat beredar di media sos | K148: Sesuai | L148: 0.73 | M148: 0.73
A149: 147 | B149: 005 | C149: 0 | D149: 0 | E149: https://metropolitan.jawapos.com/metropolitan/2604080001/5-galeri-dan-art-space-di-jakarta-ini-sering-gelar-pameran-gratis-dan-terbuka-untuk-umum | F149: metropolitan.jawapos.com | G149: 5 Galeri dan Art Space di Jakarta Ini Sering Gelar Pameran Gratis dan Terbuka untuk Umum - Jawa Pos Metropolitan | H149: Jawa Pos Metropolitan | I149: 2026-04-08 | J149: Hadirnya berbagai galeri dan art space sebagai ruang apresiasi untuk seni dan para seniman di belakangnya. Menariknya, beberapa tempat tersebut rutin menggelar pameran yang terbuka untuk umum secara g | K149: Sesuai | L149: 0.7 | M149: 0.64
A150: 148 | B150: 005 | C150: 0 | D150: 0 | E150: https://afederasi.com/golkar-tulungagung-kritik-minimnya-fasilitas-kesenian-dorong-pembangunan-galeri-seni | F150: afederasi.com | G150: Golkar Tulungagung Kritik Minimnya Fasilitas Kesenian, Dorong Pembangunan Galeri Seni - Afederasi | H150: Afederasi | I150: 2026-06-08 | J150: Join our subscribers list to get the latest news, updates and special offers directly in your inbox Tulungagung, (afederasi.com) – Partai Golkar Tulungagung menyoroti perlunya penguatan ekosistem seni | K150: Sesuai | L150: 0.7 | M150: 0.7
A151: 149 | B151: 005 | C151: 0 | D151: 0 | E151: https://bekasi.inews.id/read/714544/viral-keributan-di-mal-bekasi-utara-ternyata-dipicu-spg-digoda-spb-pameran | F151: bekasi.inews.id | G151: Viral Keributan di Mal Bekasi Utara, Ternyata Dipicu SPG Digoda SPB Pameran - iNews.ID | H151: iNews.ID | I151: 2026-09-08 | J151: Scan this QR or download app from: BEKASI , iNewsBekasi.id - Sebuah video di media sosial mendadak viral usai memperlihatkan keributan sengit di kawasan mal wilayah Bekasi Utara , Jawa Barat, pada Se | K151: Ragu | L151: 0.4 | M151: 0.4
A152: 150 | B152: 006 | C152: 1 | D152: 1 | E152: https://www.antarafoto.com/id/view/2852899/pameran-kuliner-jakarta-viral-di-padang | F152: www.antarafoto.com | G152: Pameran kuliner Jakarta Viral di Padang - antarafoto.com | H152: antarafoto.com | I152: 2026-08-29 | J152: Pengunjung melakukan transaksi digital membeli makanan saat digelarnya Festival Kuliner Gang Senggol Jakarta Viral di Padang, Sumatera Barat, Sabtu (29/8/2026). Pameran yang menampilkan 400 menu kulin | K152: Sesuai | L152: 1 | M152: 0.8
...

Sheet Per Provinsi
A1: Provinsi | B1: Jumlah tempat | C1: Viral eksplisit | D1: Kafe | E1: Restoran | F1: Wisata Alam | G1: Museum | H1: Wahana | I1: Pameran | J1: lainnya
A2: Aceh | B2: =COUNTIF(Tempat!$I$2:$I$1789,A2) -> 30 | C2: =COUNTIFS(Tempat!$I$2:$I$1789,A2,Tempat!$Q$2:$Q$1789,"Ya") -> 8 | D2: =COUNTIFS(Tempat!$I$2:$I$1789,$A2,Tempat!$D$2:$D$1789,D$1) -> 0 | E2: =COUNTIFS(Tempat!$I$2:$I$1789,$A2,Tempat!$D$2:$D$1789,E$1) -> 0 | F2: =COUNTIFS(Tempat!$I$2:$I$1789,$A2,Tempat!$D$2:$D$1789,F$1) -> 19 | G2: =COUNTIFS(Tempat!$I$2:$I$1789,$A2,Tempat!$D$2:$D$1789,G$1) -> 2 | H2: =COUNTIFS(Tempat!$I$2:$I$1789,$A2,Tempat!$D$2:$D$1789,H$1) -> 1 | I2: =COUNTIFS(Tempat!$I$2:$I$1789,$A2,Tempat!$D$2:$D$1789,I$1) -> 7 | J2: =COUNTIFS(Tempat!$I$2:$I$1789,$A2,Tempat!$D$2:$D$1789,J$1) -> 1
A3: Bali | B3: =COUNTIF(Tempat!$I$2:$I$1789,A3) -> 56 | C3: =COUNTIFS(Tempat!$I$2:$I$1789,A3,Tempat!$Q$2:$Q$1789,"Ya") -> 13 | D3: =COUNTIFS(Tempat!$I$2:$I$1789,$A3,Tempat!$D$2:$D$1789,D$1) -> 4 | E3: =COUNTIFS(Tempat!$I$2:$I$1789,$A3,Tempat!$D$2:$D$1789,E$1) -> 25 | F3: =COUNTIFS(Tempat!$I$2:$I$1789,$A3,Tempat!$D$2:$D$1789,F$1) -> 16 | G3: =COUNTIFS(Tempat!$I$2:$I$1789,$A3,Tempat!$D$2:$D$1789,G$1) -> 3 | H3: =COUNTIFS(Tempat!$I$2:$I$1789,$A3,Tempat!$D$2:$D$1789,H$1) -> 1 | I3: =COUNTIFS(Tempat!$I$2:$I$1789,$A3,Tempat!$D$2:$D$1789,I$1) -> 4 | J3: =COUNTIFS(Tempat!$I$2:$I$1789,$A3,Tempat!$D$2:$D$1789,J$1) -> 3
A4: Banten | B4: =COUNTIF(Tempat!$I$2:$I$1789,A4) -> 49 | C4: =COUNTIFS(Tempat!$I$2:$I$1789,A4,Tempat!$Q$2:$Q$1789,"Ya") -> 15 | D4: =COUNTIFS(Tempat!$I$2:$I$1789,$A4,Tempat!$D$2:$D$1789,D$1) -> 2 | E4: =COUNTIFS(Tempat!$I$2:$I$1789,$A4,Tempat!$D$2:$D$1789,E$1) -> 22 | F4: =COUNTIFS(Tempat!$I$2:$I$1789,$A4,Tempat!$D$2:$D$1789,F$1) -> 7 | G4: =COUNTIFS(Tempat!$I$2:$I$1789,$A4,Tempat!$D$2:$D$1789,G$1) -> 1 | H4: =COUNTIFS(Tempat!$I$2:$I$1789,$A4,Tempat!$D$2:$D$1789,H$1) -> 0 | I4: =COUNTIFS(Tempat!$I$2:$I$1789,$A4,Tempat!$D$2:$D$1789,I$1) -> 8 | J4: =COUNTIFS(Tempat!$I$2:$I$1789,$A4,Tempat!$D$2:$D$1789,J$1) -> 9
A5: Bengkulu | B5: =COUNTIF(Tempat!$I$2:$I$1789,A5) -> 27 | C5: =COUNTIFS(Tempat!$I$2:$I$1789,A5,Tempat!$Q$2:$Q$1789,"Ya") -> 5 | D5: =COUNTIFS(Tempat!$I$2:$I$1789,$A5,Tempat!$D$2:$D$1789,D$1) -> 0 | E5: =COUNTIFS(Tempat!$I$2:$I$1789,$A5,Tempat!$D$2:$D$1789,E$1) -> 0 | F5: =COUNTIFS(Tempat!$I$2:$I$1789,$A5,Tempat!$D$2:$D$1789,F$1) -> 16 | G5: =COUNTIFS(Tempat!$I$2:$I$1789,$A5,Tempat!$D$2:$D$1789,G$1) -> 1 | H5: =COUNTIFS(Tempat!$I$2:$I$1789,$A5,Tempat!$D$2:$D$1789,H$1) -> 0 | I5: =COUNTIFS(Tempat!$I$2:$I$1789,$A5,Tempat!$D$2:$D$1789,I$1) -> 7 | J5: =COUNTIFS(Tempat!$I$2:$I$1789,$A5,Tempat!$D$2:$D$1789,J$1) -> 3
A6: DI Yogyakarta | B6: =COUNTIF(Tempat!$I$2:$I$1789,A6) -> 104 | C6: =COUNTIFS(Tempat!$I$2:$I$1789,A6,Tempat!$Q$2:$Q$1789,"Ya") -> 36 | D6: =COUNTIFS(Tempat!$I$2:$I$1789,$A6,Tempat!$D$2:$D$1789,D$1) -> 6 | E6: =COUNTIFS(Tempat!$I$2:$I$1789,$A6,Tempat!$D$2:$D$1789,E$1) -> 40 | F6: =COUNTIFS(Tempat!$I$2:$I$1789,$A6,Tempat!$D$2:$D$1789,F$1) -> 19 | G6: =COUNTIFS(Tempat!$I$2:$I$1789,$A6,Tempat!$D$2:$D$1789,G$1) -> 4 | H6: =COUNTIFS(Tempat!$I$2:$I$1789,$A6,Tempat!$D$2:$D$1789,H$1) -> 4 | I6: =COUNTIFS(Tempat!$I$2:$I$1789,$A6,Tempat!$D$2:$D$1789,I$1) -> 14 | J6: =COUNTIFS(Tempat!$I$2:$I$1789,$A6,Tempat!$D$2:$D$1789,J$1) -> 17
A7: DKI Jakarta | B7: =COUNTIF(Tempat!$I$2:$I$1789,A7) -> 264 | C7: =COUNTIFS(Tempat!$I$2:$I$1789,A7,Tempat!$Q$2:$Q$1789,"Ya") -> 66 | D7: =COUNTIFS(Tempat!$I$2:$I$1789,$A7,Tempat!$D$2:$D$1789,D$1) -> 34 | E7: =COUNTIFS(Tempat!$I$2:$I$1789,$A7,Tempat!$D$2:$D$1789,E$1) -> 139 | F7: =COUNTIFS(Tempat!$I$2:$I$1789,$A7,Tempat!$D$2:$D$1789,F$1) -> 10 | G7: =COUNTIFS(Tempat!$I$2:$I$1789,$A7,Tempat!$D$2:$D$1789,G$1) -> 15 | H7: =COUNTIFS(Tempat!$I$2:$I$1789,$A7,Tempat!$D$2:$D$1789,H$1) -> 7 | I7: =COUNTIFS(Tempat!$I$2:$I$1789,$A7,Tempat!$D$2:$D$1789,I$1) -> 21 | J7: =COUNTIFS(Tempat!$I$2:$I$1789,$A7,Tempat!$D$2:$D$1789,J$1) -> 38
A8: Gorontalo | B8: =COUNTIF(Tempat!$I$2:$I$1789,A8) -> 17 | C8: =COUNTIFS(Tempat!$I$2:$I$1789,A8,Tempat!$Q$2:$Q$1789,"Ya") -> 0 | D8: =COUNTIFS(Tempat!$I$2:$I$1789,$A8,Tempat!$D$2:$D$1789,D$1) -> 1 | E8: =COUNTIFS(Tempat!$I$2:$I$1789,$A8,Tempat!$D$2:$D$1789,E$1) -> 3 | F8: =COUNTIFS(Tempat!$I$2:$I$1789,$A8,Tempat!$D$2:$D$1789,F$1) -> 8 | G8: =COUNTIFS(Tempat!$I$2:$I$1789,$A8,Tempat!$D$2:$D$1789,G$1) -> 2 | H8: =COUNTIFS(Tempat!$I$2:$I$1789,$A8,Tempat!$D$2:$D$1789,H$1) -> 0 | I8: =COUNTIFS(Tempat!$I$2:$I$1789,$A8,Tempat!$D$2:$D$1789,I$1) -> 2 | J8: =COUNTIFS(Tempat!$I$2:$I$1789,$A8,Tempat!$D$2:$D$1789,J$1) -> 1
A9: Jambi | B9: =COUNTIF(Tempat!$I$2:$I$1789,A9) -> 24 | C9: =COUNTIFS(Tempat!$I$2:$I$1789,A9,Tempat!$Q$2:$Q$1789,"Ya") -> 0 | D9: =COUNTIFS(Tempat!$I$2:$I$1789,$A9,Tempat!$D$2:$D$1789,D$1) -> 0 | E9: =COUNTIFS(Tempat!$I$2:$I$1789,$A9,Tempat!$D$2:$D$1789,E$1) -> 1 | F9: =COUNTIFS(Tempat!$I$2:$I$1789,$A9,Tempat!$D$2:$D$1789,F$1) -> 10 | G9: =COUNTIFS(Tempat!$I$2:$I$1789,$A9,Tempat!$D$2:$D$1789,G$1) -> 9 | H9: =COUNTIFS(Tempat!$I$2:$I$1789,$A9,Tempat!$D$2:$D$1789,H$1) -> 0 | I9: =COUNTIFS(Tempat!$I$2:$I$1789,$A9,Tempat!$D$2:$D$1789,I$1) -> 3 | J9: =COUNTIFS(Tempat!$I$2:$I$1789,$A9,Tempat!$D$2:$D$1789,J$1) -> 1
A10: Jawa Barat | B10: =COUNTIF(Tempat!$I$2:$I$1789,A10) -> 269 | C10: =COUNTIFS(Tempat!$I$2:$I$1789,A10,Tempat!$Q$2:$Q$1789,"Ya") -> 79 | D10: =COUNTIFS(Tempat!$I$2:$I$1789,$A10,Tempat!$D$2:$D$1789,D$1) -> 44 | E10: =COUNTIFS(Tempat!$I$2:$I$1789,$A10,Tempat!$D$2:$D$1789,E$1) -> 96 | F10: =COUNTIFS(Tempat!$I$2:$I$1789,$A10,Tempat!$D$2:$D$1789,F$1) -> 45 | G10: =COUNTIFS(Tempat!$I$2:$I$1789,$A10,Tempat!$D$2:$D$1789,G$1) -> 11 | H10: =COUNTIFS(Tempat!$I$2:$I$1789,$A10,Tempat!$D$2:$D$1789,H$1) -> 13 | I10: =COUNTIFS(Tempat!$I$2:$I$1789,$A10,Tempat!$D$2:$D$1789,I$1) -> 18 | J10: =COUNTIFS(Tempat!$I$2:$I$1789,$A10,Tempat!$D$2:$D$1789,J$1) -> 42
A11: Jawa Tengah | B11: =COUNTIF(Tempat!$I$2:$I$1789,A11) -> 173 | C11: =COUNTIFS(Tempat!$I$2:$I$1789,A11,Tempat!$Q$2:$Q$1789,"Ya") -> 45 | D11: =COUNTIFS(Tempat!$I$2:$I$1789,$A11,Tempat!$D$2:$D$1789,D$1) -> 30 | E11: =COUNTIFS(Tempat!$I$2:$I$1789,$A11,Tempat!$D$2:$D$1789,E$1) -> 48 | F11: =COUNTIFS(Tempat!$I$2:$I$1789,$A11,Tempat!$D$2:$D$1789,F$1) -> 23 | G11: =COUNTIFS(Tempat!$I$2:$I$1789,$A11,Tempat!$D$2:$D$1789,G$1) -> 19 | H11: =COUNTIFS(Tempat!$I$2:$I$1789,$A11,Tempat!$D$2:$D$1789,H$1) -> 6 | I11: =COUNTIFS(Tempat!$I$2:$I$1789,$A11,Tempat!$D$2:$D$1789,I$1) -> 21 | J11: =COUNTIFS(Tempat!$I$2:$I$1789,$A11,Tempat!$D$2:$D$1789,J$1) -> 26
A12: Jawa Timur | B12: =COUNTIF(Tempat!$I$2:$I$1789,A12) -> 183 | C12: =COUNTIFS(Tempat!$I$2:$I$1789,A12,Tempat!$Q$2:$Q$1789,"Ya") -> 46 | D12: =COUNTIFS(Tempat!$I$2:$I$1789,$A12,Tempat!$D$2:$D$1789,D$1) -> 23 | E12: =COUNTIFS(Tempat!$I$2:$I$1789,$A12,Tempat!$D$2:$D$1789,E$1) -> 69 | F12: =COUNTIFS(Tempat!$I$2:$I$1789,$A12,Tempat!$D$2:$D$1789,F$1) -> 32 | G12: =COUNTIFS(Tempat!$I$2:$I$1789,$A12,Tempat!$D$2:$D$1789,G$1) -> 9 | H12: =COUNTIFS(Tempat!$I$2:$I$1789,$A12,Tempat!$D$2:$D$1789,H$1) -> 11 | I12: =COUNTIFS(Tempat!$I$2:$I$1789,$A12,Tempat!$D$2:$D$1789,I$1) -> 17 | J12: =COUNTIFS(Tempat!$I$2:$I$1789,$A12,Tempat!$D$2:$D$1789,J$1) -> 22
A13: Kalimantan Barat | B13: =COUNTIF(Tempat!$I$2:$I$1789,A13) -> 24 | C13: =COUNTIFS(Tempat!$I$2:$I$1789,A13,Tempat!$Q$2:$Q$1789,"Ya") -> 5 | D13: =COUNTIFS(Tempat!$I$2:$I$1789,$A13,Tempat!$D$2:$D$1789,D$1) -> 4 | E13: =COUNTIFS(Tempat!$I$2:$I$1789,$A13,Tempat!$D$2:$D$1789,E$1) -> 13 | F13: =COUNTIFS(Tempat!$I$2:$I$1789,$A13,Tempat!$D$2:$D$1789,F$1) -> 2 | G13: =COUNTIFS(Tempat!$I$2:$I$1789,$A13,Tempat!$D$2:$D$1789,G$1) -> 0 | H13: =COUNTIFS(Tempat!$I$2:$I$1789,$A13,Tempat!$D$2:$D$1789,H$1) -> 0 | I13: =COUNTIFS(Tempat!$I$2:$I$1789,$A13,Tempat!$D$2:$D$1789,I$1) -> 1 | J13: =COUNTIFS(Tempat!$I$2:$I$1789,$A13,Tempat!$D$2:$D$1789,J$1) -> 4
... A39: Sumatera Utara | B39: =COUNTIF(Tempat!$I$2:$I$1789,A39) -> 53 | C39: =COUNTIFS(Tempat!$I$2:$I$1789,A39,Tempat!$Q$2:$Q$1789,"Ya") -> 18 | D39: =COUNTIFS(Tempat!$I$2:$I$1789,$A39,Tempat!$D$2:$D$1789,D$1) -> 10 | E39: =COUNTIFS(Tempat!$I$2:$I$1789,$A39,Tempat!$D$2:$D$1789,E$1) -> 13 | F39: =COUNTIFS(Tempat!$I$2:$I$1789,$A39,Tempat!$D$2:$D$1789,F$1) -> 15 | G39: =COUNTIFS(Tempat!$I$2:$I$1789,$A39,Tempat!$D$2:$D$1789,G$1) -> 1 | H39: =COUNTIFS(Tempat!$I$2:$I$1789,$A39,Tempat!$D$2:$D$1789,H$1) -> 1 | I39: =COUNTIFS(Tempat!$I$2:$I$1789,$A39,Tempat!$D$2:$D$1789,I$1) -> 9 | J39: =COUNTIFS(Tempat!$I$2:$I$1789,$A39,Tempat!$D$2:$D$1789,J$1) -> 4
A40: Tanpa provinsi (luar negeri / tidak jelas) | B40: =COUNTA(Tempat!A2:A1789)-SUM(B2:B39) -> 44
